<?xml version="1.0" ?>
<robot name="URDF">

<material name="silver">
  <color rgba="0.700 0.700 0.700 1.000"/>
</material>

<link name="base_link">
  <inertial>
    <origin xyz="0.21027456882143253 -0.05192508200472862 -0.012773728032096936" rpy="0 0 0"/>
    <mass value="1.965537963955518"/>
    <inertia ixx="0.0018963137482149346" iyy="0.0018963122502908825" izz="0.002897425073331114" ixy="2.973470965977887e-09" iyz="-1.122633622348268e-09" ixz="1.002449897397062e-09"/>
  </inertial>
  <visual>
    <origin xyz="0 0 0" rpy="0 0 0"/>
    <geometry>
      <mesh filename="meshes/base_link.stl" scale="0.001 0.001 0.001"/>
    </geometry>
    <material name="silver"/>
    <material/>
  </visual>
  <collision>
    <origin xyz="0 0 0" rpy="0 0 0"/>
    <geometry>
      <mesh filename="meshes/base_link.stl" scale="0.001 0.001 0.001"/>
    </geometry>
  </collision>
</link>

<link name="finger_link121">
  <inertial>
    <origin xyz="-0.05799669988999707 -3.608783178993963e-05 0.0012143810206116086" rpy="0 0 0"/>
    <mass value="0.5923964835612685"/>
    <inertia ixx="0.00012778634615537884" iyy="0.00043862033204555406" izz="0.0004967041029092702" ixy="-5.718019806204462e-06" iyz="-1.4276741060023537e-08" ixz="-1.540606152980023e-05"/>
  </inertial>
  <visual>
    <origin xyz="-0.109825 0.052925 -0.0" rpy="0 0 0"/>
    <geometry>
      <mesh filename="meshes/finger_link121.stl" scale="0.001 0.001 0.001"/>
    </geometry>
    <material name="silver"/>
    <material/>
  </visual>
  <collision>
    <origin xyz="-0.109825 0.052925 -0.0" rpy="0 0 0"/>
    <geometry>
      <mesh filename="meshes/finger_link121.stl" scale="0.001 0.001 0.001"/>
    </geometry>
  </collision>
</link>

<link name="finger_link131">
  <inertial>
    <origin xyz="-0.057765004769379735 -3.624675652125903e-05 0.0012630886709608508" rpy="0 0 0"/>
    <mass value="0.5898232192882595"/>
    <inertia ixx="0.0001272612390084474" iyy="0.00043101250428518375" izz="0.0004892171629736469" ixy="-5.722969316268307e-06" iyz="-1.531801231859217e-08" ixz="-1.3874799189148437e-05"/>
  </inertial>
  <visual>
    <origin xyz="-0.02709 0.052925 -0.0" rpy="0 0 0"/>
    <geometry>
      <mesh filename="meshes/finger_link131.stl" scale="0.001 0.001 0.001"/>
    </geometry>
    <material name="silver"/>
    <material/>
  </visual>
  <collision>
    <origin xyz="-0.02709 0.052925 -0.0" rpy="0 0 0"/>
    <geometry>
      <mesh filename="meshes/finger_link131.stl" scale="0.001 0.001 0.001"/>
    </geometry>
  </collision>
</link>

<link name="finger1_ef1">
  <inertial>
    <origin xyz="-0.017887627502148867 0.0004573353067871058 -0.0003386580455759995" rpy="0 0 0"/>
    <mass value="0.07986065950945902"/>
    <inertia ixx="2.6825696754000837e-05" iyy="1.400445156223755e-05" izz="3.648814462563774e-05" ixy="-1.236357807567483e-06" iyz="-6.170233186402577e-08" ixz="-4.08567468943111e-07"/>
  </inertial>
  <visual>
    <origin xyz="0.055645 0.052925 -0.0" rpy="0 0 0"/>
    <geometry>
      <mesh filename="meshes/finger1_ef1.stl" scale="0.001 0.001 0.001"/>
    </geometry>
    <material name="silver"/>
    <material/>
  </visual>
  <collision>
    <origin xyz="0.055645 0.052925 -0.0" rpy="0 0 0"/>
    <geometry>
      <mesh filename="meshes/finger1_ef1.stl" scale="0.001 0.001 0.001"/>
    </geometry>
  </collision>
</link>

<link name="finger_link211">
  <inertial>
    <origin xyz="0.023503468036998793 0.041176003842312334 0.009232693983073387" rpy="0 0 0"/>
    <mass value="0.33961269438037617"/>
    <inertia ixx="0.00017739336089992992" iyy="0.00010410023030453172" izz="0.00019147396755265014" ixy="-6.088100651440234e-05" iyz="-2.692769923765825e-05" ixz="-1.5050892191462324e-05"/>
  </inertial>
  <visual>
    <origin xyz="-0.231021 0.013991 0.01388" rpy="0 0 0"/>
    <geometry>
      <mesh filename="meshes/finger_link211.stl" scale="0.001 0.001 0.001"/>
    </geometry>
    <material name="silver"/>
    <material/>
  </visual>
  <collision>
    <origin xyz="-0.231021 0.013991 0.01388" rpy="0 0 0"/>
    <geometry>
      <mesh filename="meshes/finger_link211.stl" scale="0.001 0.001 0.001"/>
    </geometry>
  </collision>
</link>

<link name="finger_link221">
  <inertial>
    <origin xyz="0.028967318371381445 0.05024448235772762 0.001214381020611615" rpy="0 0 0"/>
    <mass value="0.5923964835612682"/>
    <inertia ixx="0.0003658637859845267" iyy="0.00020054289221640986" izz="0.0004967041029092789" ixy="-0.00013173605416713467" iyz="1.334917902760315e-05" ixz="7.6906667444588e-06"/>
  </inertial>
  <visual>
    <origin xyz="-0.259633 -0.035567 -0.0" rpy="0 0 0"/>
    <geometry>
      <mesh filename="meshes/finger_link221.stl" scale="0.001 0.001 0.001"/>
    </geometry>
    <material name="silver"/>
    <material/>
  </visual>
  <collision>
    <origin xyz="-0.259633 -0.035567 -0.0" rpy="0 0 0"/>
    <geometry>
      <mesh filename="meshes/finger_link221.stl" scale="0.001 0.001 0.001"/>
    </geometry>
  </collision>
</link>

<link name="finger_link231">
  <inertial>
    <origin xyz="0.028966733545055134 0.05024394983760365 0.0012143810161802681" rpy="0 0 0"/>
    <mass value="0.5923964896980345"/>
    <inertia ixx="0.0003658637873439896" iyy="0.000200542897177719" izz="0.0004967041092763247" ixy="-0.00013173605685385184" iyz="1.3349179133433439e-05" ixz="7.690666879132322e-06"/>
  </inertial>
  <visual>
    <origin xyz="-0.301001 -0.107218 -0.0" rpy="0 0 0"/>
    <geometry>
      <mesh filename="meshes/finger_link231.stl" scale="0.001 0.001 0.001"/>
    </geometry>
    <material name="silver"/>
    <material/>
  </visual>
  <collision>
    <origin xyz="-0.301001 -0.107218 -0.0" rpy="0 0 0"/>
    <geometry>
      <mesh filename="meshes/finger_link231.stl" scale="0.001 0.001 0.001"/>
    </geometry>
  </collision>
</link>

<link name="finger2_ef1">
  <inertial>
    <origin xyz="0.00934009915027989 0.015262518742544612 -0.0003386580455759962" rpy="0 0 0"/>
    <mass value="0.07986065950945906"/>
    <inertia ixx="1.828048012969888e-05" iyy="2.2549668186535796e-05" izz="3.648814462563557e-05" ixy="6.169940925893069e-06" iyz="3.846809731966711e-07" ixz="1.5084794760459843e-07"/>
  </inertial>
  <visual>
    <origin xyz="-0.342368 -0.178868 -0.0" rpy="0 0 0"/>
    <geometry>
      <mesh filename="meshes/finger2_ef1.stl" scale="0.001 0.001 0.001"/>
    </geometry>
    <material name="silver"/>
    <material/>
  </visual>
  <collision>
    <origin xyz="-0.342368 -0.178868 -0.0" rpy="0 0 0"/>
    <geometry>
      <mesh filename="meshes/finger2_ef1.stl" scale="0.001 0.001 0.001"/>
    </geometry>
  </collision>
</link>

<link name="finger_link311">
  <inertial>
    <origin xyz="0.023907785811692617 -0.04094259415385859 0.009232693983073383" rpy="0 0 0"/>
    <mass value="0.33961269438037617"/>
    <inertia ixx="0.00017514801120281295" iyy="0.00010634558000168284" izz="0.0001914739675526675" ixy="6.217735976646668e-05" iyz="2.6498304606256955e-05" ixz="-1.579462550954598e-05"/>
  </inertial>
  <visual>
    <origin xyz="-0.232753 0.088859 0.01388" rpy="0 0 0"/>
    <geometry>
      <mesh filename="meshes/finger_link311.stl" scale="0.001 0.001 0.001"/>
    </geometry>
    <material name="silver"/>
    <material/>
  </visual>
  <collision>
    <origin xyz="-0.232753 0.088859 0.01388" rpy="0 0 0"/>
    <geometry>
      <mesh filename="meshes/finger_link311.stl" scale="0.001 0.001 0.001"/>
    </geometry>
  </collision>
</link>

<link name="finger_link321">
  <inertial>
    <origin xyz="0.029029880373273143 -0.050208385456697924 0.0012143810206116192" rpy="0 0 0"/>
    <mass value="0.592396483561268"/>
    <inertia ixx="0.0003559598851614887" iyy="0.00021044679303942188" izz="0.0004967041029092512" ixy="0.00013745407397333653" iyz="-1.3334902286543188e-05" ixz="7.71539478534118e-06"/>
  </inertial>
  <visual>
    <origin xyz="-0.261365 0.138417 -0.0" rpy="0 0 0"/>
    <geometry>
      <mesh filename="meshes/finger_link321.stl" scale="0.001 0.001 0.001"/>
    </geometry>
    <material name="silver"/>
    <material/>
  </visual>
  <collision>
    <origin xyz="-0.261365 0.138417 -0.0" rpy="0 0 0"/>
    <geometry>
      <mesh filename="meshes/finger_link321.stl" scale="0.001 0.001 0.001"/>
    </geometry>
  </collision>
</link>

<link name="finger_link331">
  <inertial>
    <origin xyz="0.029029297822457167 -0.05020785128272656 0.0012143810206116262" rpy="0 0 0"/>
    <mass value="0.592396483561268"/>
    <inertia ixx="0.0003559598851615234" iyy="0.00021044679303953984" izz="0.0004967041029092234" ixy="0.00013745407397327408" iyz="-1.333490228654411e-05" ixz="7.715394785340394e-06"/>
  </inertial>
  <visual>
    <origin xyz="-0.302733 0.210068 -0.0" rpy="0 0 0"/>
    <geometry>
      <mesh filename="meshes/finger_link331.stl" scale="0.001 0.001 0.001"/>
    </geometry>
    <material name="silver"/>
    <material/>
  </visual>
  <collision>
    <origin xyz="-0.302733 0.210068 -0.0" rpy="0 0 0"/>
    <geometry>
      <mesh filename="meshes/finger_link331.stl" scale="0.001 0.001 0.001"/>
    </geometry>
  </collision>
</link>

<link name="finger3_ef1">
  <inertial>
    <origin xyz="0.008548027206526254 -0.015719844980091824 -0.0003386580455759947" rpy="0 0 0"/>
    <mass value="0.07986065950945924"/>
    <inertia ixx="1.61390455906572e-05" iyy="2.4691102725576605e-05" izz="3.648814462563557e-05" ixy="-4.933583118326562e-06" iyz="-3.2297864133265275e-07" ixz="2.5771952133854305e-07"/>
  </inertial>
  <visual>
    <origin xyz="-0.3441 0.281718 -0.0" rpy="0 0 0"/>
    <geometry>
      <mesh filename="meshes/finger3_ef1.stl" scale="0.001 0.001 0.001"/>
    </geometry>
    <material name="silver"/>
    <material/>
  </visual>
  <collision>
    <origin xyz="-0.3441 0.281718 -0.0" rpy="0 0 0"/>
    <geometry>
      <mesh filename="meshes/finger3_ef1.stl" scale="0.001 0.001 0.001"/>
    </geometry>
  </collision>
</link>

<link name="finger_link111">
  <inertial>
    <origin xyz="-0.047410754994033424 -0.0002334006192142024 0.00923269398307338" rpy="0 0 0"/>
    <mass value="0.3396126943803763"/>
    <inertia ixx="6.969901470393663e-05" iyy="0.00021179457650051525" izz="0.0001914739675526406" ixy="-1.296353252055668e-06" iyz="4.2939463140193e-07" ixz="3.084551770101015e-05"/>
  </inertial>
  <visual>
    <origin xyz="-0.167049 0.052925 0.01388" rpy="0 0 0"/>
    <geometry>
      <mesh filename="meshes/finger_link111.stl" scale="0.001 0.001 0.001"/>
    </geometry>
    <material name="silver"/>
    <material/>
  </visual>
  <collision>
    <origin xyz="-0.167049 0.052925 0.01388" rpy="0 0 0"/>
    <geometry>
      <mesh filename="meshes/finger_link111.stl" scale="0.001 0.001 0.001"/>
    </geometry>
  </collision>
</link>

<joint name="finger1_joint1" type="revolute">
  <origin xyz="-0.057224 0.0 0.01388" rpy="0 0 0"/>
  <parent link="finger_link111"/>
  <child link="finger_link121"/>
  <axis xyz="-0.0 1.0 -0.0"/>
  <limit upper="1.570796" lower="0.0" effort="100" velocity="100"/>
</joint>
<transmission name="finger1_joint1_tran">
  <type>transmission_interface/SimpleTransmission</type>
  <joint name="finger1_joint1">
    <hardwareInterface>PositionJointInterface</hardwareInterface>
  </joint>
  <actuator name="finger1_joint1_actr">
    <hardwareInterface>PositionJointInterface</hardwareInterface>
    <mechanicalReduction>1</mechanicalReduction>
  </actuator>
</transmission>

<joint name="finger1_joint2" type="revolute">
  <origin xyz="-0.082735 0.0 0.0" rpy="0 0 0"/>
  <parent link="finger_link121"/>
  <child link="finger_link131"/>
  <axis xyz="0.0 1.0 -0.0"/>
  <limit upper="1.570796" lower="0.0" effort="100" velocity="100"/>
</joint>
<transmission name="finger1_joint2_tran">
  <type>transmission_interface/SimpleTransmission</type>
  <joint name="finger1_joint2">
    <hardwareInterface>PositionJointInterface</hardwareInterface>
  </joint>
  <actuator name="finger1_joint2_actr">
    <hardwareInterface>PositionJointInterface</hardwareInterface>
    <mechanicalReduction>1</mechanicalReduction>
  </actuator>
</transmission>

<joint name="finger1_joint3" type="revolute">
  <origin xyz="-0.082735 0.0 0.0" rpy="0 0 0"/>
  <parent link="finger_link131"/>
  <child link="finger1_ef1"/>
  <axis xyz="-0.0 1.0 -0.0"/>
  <limit upper="1.570796" lower="-1.570796" effort="100" velocity="100"/>
</joint>
<transmission name="finger1_joint3_tran">
  <type>transmission_interface/SimpleTransmission</type>
  <joint name="finger1_joint3">
    <hardwareInterface>PositionJointInterface</hardwareInterface>
  </joint>
  <actuator name="finger1_joint3_actr">
    <hardwareInterface>PositionJointInterface</hardwareInterface>
    <mechanicalReduction>1</mechanicalReduction>
  </actuator>
</transmission>

<joint name="finger2_palm" type="revolute">
  <origin xyz="0.231021 -0.013991 -0.01388" rpy="0 0 0"/>
  <parent link="base_link"/>
  <child link="finger_link211"/>
  <axis xyz="0.0 -0.0 1.0"/>
  <limit upper="1.047198" lower="-1.047198" effort="100" velocity="100"/>
</joint>
<transmission name="finger2_palm_tran">
  <type>transmission_interface/SimpleTransmission</type>
  <joint name="finger2_palm">
    <hardwareInterface>PositionJointInterface</hardwareInterface>
  </joint>
  <actuator name="finger2_palm_actr">
    <hardwareInterface>PositionJointInterface</hardwareInterface>
    <mechanicalReduction>1</mechanicalReduction>
  </actuator>
</transmission>

<joint name="finger2_joint1" type="revolute">
  <origin xyz="0.028612 0.049558 0.01388" rpy="0 0 0"/>
  <parent link="finger_link211"/>
  <child link="finger_link221"/>
  <axis xyz="0.866025 -0.5 -0.0"/>
  <limit upper="1.570796" lower="0.0" effort="100" velocity="100"/>
</joint>
<transmission name="finger2_joint1_tran">
  <type>transmission_interface/SimpleTransmission</type>
  <joint name="finger2_joint1">
    <hardwareInterface>PositionJointInterface</hardwareInterface>
  </joint>
  <actuator name="finger2_joint1_actr">
    <hardwareInterface>PositionJointInterface</hardwareInterface>
    <mechanicalReduction>1</mechanicalReduction>
  </actuator>
</transmission>

<joint name="finger2_joint2" type="revolute">
  <origin xyz="0.041368 0.071651 0.0" rpy="0 0 0"/>
  <parent link="finger_link221"/>
  <child link="finger_link231"/>
  <axis xyz="0.866025 -0.5 -0.0"/>
  <limit upper="1.570796" lower="0.0" effort="100" velocity="100"/>
</joint>
<transmission name="finger2_joint2_tran">
  <type>transmission_interface/SimpleTransmission</type>
  <joint name="finger2_joint2">
    <hardwareInterface>PositionJointInterface</hardwareInterface>
  </joint>
  <actuator name="finger2_joint2_actr">
    <hardwareInterface>PositionJointInterface</hardwareInterface>
    <mechanicalReduction>1</mechanicalReduction>
  </actuator>
</transmission>

<joint name="finger2_joint3" type="revolute">
  <origin xyz="0.041367 0.07165 0.0" rpy="0 0 0"/>
  <parent link="finger_link231"/>
  <child link="finger2_ef1"/>
  <axis xyz="0.866025 -0.5 -0.0"/>
  <limit upper="1.570796" lower="0.0" effort="100" velocity="100"/>
</joint>
<transmission name="finger2_joint3_tran">
  <type>transmission_interface/SimpleTransmission</type>
  <joint name="finger2_joint3">
    <hardwareInterface>PositionJointInterface</hardwareInterface>
  </joint>
  <actuator name="finger2_joint3_actr">
    <hardwareInterface>PositionJointInterface</hardwareInterface>
    <mechanicalReduction>1</mechanicalReduction>
  </actuator>
</transmission>

<joint name="finger3_palm" type="revolute">
  <origin xyz="0.232753 -0.088859 -0.01388" rpy="0 0 0"/>
  <parent link="base_link"/>
  <child link="finger_link311"/>
  <axis xyz="-0.0 0.0 1.0"/>
  <limit upper="1.047198" lower="-1.047198" effort="100" velocity="100"/>
</joint>
<transmission name="finger3_palm_tran">
  <type>transmission_interface/SimpleTransmission</type>
  <joint name="finger3_palm">
    <hardwareInterface>PositionJointInterface</hardwareInterface>
  </joint>
  <actuator name="finger3_palm_actr">
    <hardwareInterface>PositionJointInterface</hardwareInterface>
    <mechanicalReduction>1</mechanicalReduction>
  </actuator>
</transmission>

<joint name="finger3_joint1" type="revolute">
  <origin xyz="0.028612 -0.049558 0.01388" rpy="0 0 0"/>
  <parent link="finger_link311"/>
  <child link="finger_link321"/>
  <axis xyz="-0.866025 -0.5 -0.0"/>
  <limit upper="1.570796" lower="0.0" effort="100" velocity="100"/>
</joint>
<transmission name="finger3_joint1_tran">
  <type>transmission_interface/SimpleTransmission</type>
  <joint name="finger3_joint1">
    <hardwareInterface>PositionJointInterface</hardwareInterface>
  </joint>
  <actuator name="finger3_joint1_actr">
    <hardwareInterface>PositionJointInterface</hardwareInterface>
    <mechanicalReduction>1</mechanicalReduction>
  </actuator>
</transmission>

<joint name="finger3_joint2" type="revolute">
  <origin xyz="0.041368 -0.071651 0.0" rpy="0 0 0"/>
  <parent link="finger_link321"/>
  <child link="finger_link331"/>
  <axis xyz="-0.866025 -0.5 0.0"/>
  <limit upper="1.570796" lower="0.0" effort="100" velocity="100"/>
</joint>
<transmission name="finger3_joint2_tran">
  <type>transmission_interface/SimpleTransmission</type>
  <joint name="finger3_joint2">
    <hardwareInterface>PositionJointInterface</hardwareInterface>
  </joint>
  <actuator name="finger3_joint2_actr">
    <hardwareInterface>PositionJointInterface</hardwareInterface>
    <mechanicalReduction>1</mechanicalReduction>
  </actuator>
</transmission>

<joint name="finger3_joint3" type="revolute">
  <origin xyz="0.041367 -0.07165 0.0" rpy="0 0 0"/>
  <parent link="finger_link331"/>
  <child link="finger3_ef1"/>
  <axis xyz="-0.866025 -0.5 0.0"/>
  <limit upper="1.570796" lower="0.0" effort="100" velocity="100"/>
</joint>
<transmission name="finger3_joint3_tran">
  <type>transmission_interface/SimpleTransmission</type>
  <joint name="finger3_joint3">
    <hardwareInterface>PositionJointInterface</hardwareInterface>
  </joint>
  <actuator name="finger3_joint3_actr">
    <hardwareInterface>PositionJointInterface</hardwareInterface>
    <mechanicalReduction>1</mechanicalReduction>
  </actuator>
</transmission>

<joint name="finger1_palm" type="revolute">
  <origin xyz="0.167049 -0.052925 -0.01388" rpy="0 0 0"/>
  <parent link="base_link"/>
  <child link="finger_link111"/>
  <axis xyz="0.0 0.0 1.0"/>
  <limit upper="1.047198" lower="-1.047198" effort="100" velocity="100"/>
</joint>
<transmission name="finger1_palm_tran">
  <type>transmission_interface/SimpleTransmission</type>
  <joint name="finger1_palm">
    <hardwareInterface>PositionJointInterface</hardwareInterface>
  </joint>
  <actuator name="finger1_palm_actr">
    <hardwareInterface>PositionJointInterface</hardwareInterface>
    <mechanicalReduction>1</mechanicalReduction>
  </actuator>
</transmission>

</robot>
