<?xml version="1.0" ?>
<robot name="URDF">

<material name="silver">
  <color rgba="0.700 0.700 0.700 1.000"/>
</material>

<link name="base_link">
  <inertial>
    <origin xyz="0.21027456882143253 -0.05192508200472862 -0.012773728032096934" rpy="0 0 0"/>
    <mass value="1.9655379639555184"/>
    <inertia ixx="0.0018963137482149338" iyy="0.0018963122502908686" izz="0.0028974250733311002" ixy="2.97347096250844e-09" iyz="-1.1226336227819489e-09" ixz="1.0024498965297002e-09"/>
  </inertial>
  <visual>
    <origin xyz="0 0 0" rpy="0 0 0"/>
    <geometry>
      <mesh filename="meshes/base_link.stl" scale="0.001 0.001 0.001"/>
    </geometry>
    <material name="silver"/>
    <material/>
  </visual>
  <collision>
    <origin xyz="0 0 0" rpy="0 0 0"/>
    <geometry>
      <mesh filename="meshes/base_link.stl" scale="0.001 0.001 0.001"/>
    </geometry>
  </collision>
</link>

<link name="finger_link121">
  <inertial>
    <origin xyz="-0.05799669988999707 -3.608783178993963e-05 0.00121438102061161" rpy="0 0 0"/>
    <mass value="0.5923964835612685"/>
    <inertia ixx="0.00012778634615537884" iyy="0.00043862033204555406" izz="0.0004967041029092702" ixy="-5.718019806204462e-06" iyz="-1.4276741059989656e-08" ixz="-1.5406061529800197e-05"/>
  </inertial>
  <visual>
    <origin xyz="-0.109825 0.052925 -0.0" rpy="0 0 0"/>
    <geometry>
      <mesh filename="meshes/finger_link121.stl" scale="0.001 0.001 0.001"/>
    </geometry>
    <material name="silver"/>
    <material/>
  </visual>
  <collision>
    <origin xyz="-0.109825 0.052925 -0.0" rpy="0 0 0"/>
    <geometry>
      <mesh filename="meshes/finger_link121.stl" scale="0.001 0.001 0.001"/>
    </geometry>
  </collision>
</link>

<link name="finger_link131">
  <inertial>
    <origin xyz="-0.057765004769379735 -3.624675652125903e-05 0.001263088670960852" rpy="0 0 0"/>
    <mass value="0.5898232192882595"/>
    <inertia ixx="0.0001272612390084474" iyy="0.00043101250428518364" izz="0.0004892171629736469" ixy="-5.722969316268307e-06" iyz="-1.531801231857184e-08" ixz="-1.3874799189148414e-05"/>
  </inertial>
  <visual>
    <origin xyz="-0.02709 0.052925 -0.0" rpy="0 0 0"/>
    <geometry>
      <mesh filename="meshes/finger_link131.stl" scale="0.001 0.001 0.001"/>
    </geometry>
    <material name="silver"/>
    <material/>
  </visual>
  <collision>
    <origin xyz="-0.02709 0.052925 -0.0" rpy="0 0 0"/>
    <geometry>
      <mesh filename="meshes/finger_link131.stl" scale="0.001 0.001 0.001"/>
    </geometry>
  </collision>
</link>

<link name="finger1_ef1">
  <inertial>
    <origin xyz="-0.03483021585233799 0.00019839455909273496 -0.0006880018002984952" rpy="0 0 0"/>
    <mass value="0.23659461522625636"/>
    <inertia ixx="5.455432759857246e-05" iyy="6.20551156285949e-05" izz="0.00010170804414663193" ixy="-1.8753096483758742e-06" iyz="-3.2902451898018223e-08" ixz="-1.341950598108509e-06"/>
  </inertial>
  <visual>
    <origin xyz="0.055645 0.052925 -0.0" rpy="0 0 0"/>
    <geometry>
      <mesh filename="meshes/finger1_ef1.stl" scale="0.001 0.001 0.001"/>
    </geometry>
    <material name="silver"/>
    <material/>
  </visual>
  <collision>
    <origin xyz="0.055645 0.052925 -0.0" rpy="0 0 0"/>
    <geometry>
      <mesh filename="meshes/finger1_ef1.stl" scale="0.001 0.001 0.001"/>
    </geometry>
  </collision>
</link>

<link name="finger_link211">
  <inertial>
    <origin xyz="0.023503468036998793 0.041176003842312334 0.009232693983073387" rpy="0 0 0"/>
    <mass value="0.33961269438037617"/>
    <inertia ixx="0.00017739336089992992" iyy="0.00010410023030453172" izz="0.00019147396755265014" ixy="-6.088100651440234e-05" iyz="-2.6927699237658262e-05" ixz="-1.5050892191462324e-05"/>
  </inertial>
  <visual>
    <origin xyz="-0.231021 0.013991 0.01388" rpy="0 0 0"/>
    <geometry>
      <mesh filename="meshes/finger_link211.stl" scale="0.001 0.001 0.001"/>
    </geometry>
    <material name="silver"/>
    <material/>
  </visual>
  <collision>
    <origin xyz="-0.231021 0.013991 0.01388" rpy="0 0 0"/>
    <geometry>
      <mesh filename="meshes/finger_link211.stl" scale="0.001 0.001 0.001"/>
    </geometry>
  </collision>
</link>

<link name="finger_link221">
  <inertial>
    <origin xyz="0.028967318371381445 0.05024448235772763 0.001214381020611615" rpy="0 0 0"/>
    <mass value="0.5923964835612682"/>
    <inertia ixx="0.00036586378598452585" iyy="0.00020054289221640986" izz="0.0004967041029092789" ixy="-0.00013173605416713294" iyz="1.3349179027603144e-05" ixz="7.690666744458827e-06"/>
  </inertial>
  <visual>
    <origin xyz="-0.259633 -0.035567 -0.0" rpy="0 0 0"/>
    <geometry>
      <mesh filename="meshes/finger_link221.stl" scale="0.001 0.001 0.001"/>
    </geometry>
    <material name="silver"/>
    <material/>
  </visual>
  <collision>
    <origin xyz="-0.259633 -0.035567 -0.0" rpy="0 0 0"/>
    <geometry>
      <mesh filename="meshes/finger_link221.stl" scale="0.001 0.001 0.001"/>
    </geometry>
  </collision>
</link>

<link name="finger_link231">
  <inertial>
    <origin xyz="0.028850833470314197 0.05004351993008056 0.0012630886701467106" rpy="0 0 0"/>
    <mass value="0.5898232250623396"/>
    <inertia ixx="0.00036003092658365085" iyy="0.00019824282348428202" izz="0.0004892171698338693" ixy="-0.00012866667432076886" iyz="1.2023587657172087e-05" ixz="6.92413388056747e-06"/>
  </inertial>
  <visual>
    <origin xyz="-0.301001 -0.107218 -0.0" rpy="0 0 0"/>
    <geometry>
      <mesh filename="meshes/finger_link231.stl" scale="0.001 0.001 0.001"/>
    </geometry>
    <material name="silver"/>
    <material/>
  </visual>
  <collision>
    <origin xyz="-0.301001 -0.107218 -0.0" rpy="0 0 0"/>
    <geometry>
      <mesh filename="meshes/finger_link231.stl" scale="0.001 0.001 0.001"/>
    </geometry>
  </collision>
</link>

<link name="finger_link311">
  <inertial>
    <origin xyz="0.023907785811692617 -0.04094259415385859 0.009232693983073387" rpy="0 0 0"/>
    <mass value="0.33961269438037617"/>
    <inertia ixx="0.00017514801120281295" iyy="0.00010634558000168284" izz="0.0001914739675526675" ixy="6.217735976646668e-05" iyz="2.64983046062569e-05" ixz="-1.579462550954587e-05"/>
  </inertial>
  <visual>
    <origin xyz="-0.232753 0.088859 0.01388" rpy="0 0 0"/>
    <geometry>
      <mesh filename="meshes/finger_link311.stl" scale="0.001 0.001 0.001"/>
    </geometry>
    <material name="silver"/>
    <material/>
  </visual>
  <collision>
    <origin xyz="-0.232753 0.088859 0.01388" rpy="0 0 0"/>
    <geometry>
      <mesh filename="meshes/finger_link311.stl" scale="0.001 0.001 0.001"/>
    </geometry>
  </collision>
</link>

<link name="finger_link321">
  <inertial>
    <origin xyz="0.029029880373273143 -0.050208385456697924 0.0012143810206116199" rpy="0 0 0"/>
    <mass value="0.592396483561268"/>
    <inertia ixx="0.0003559598851614887" iyy="0.00021044679303942188" izz="0.0004967041029092512" ixy="0.00013745407397333653" iyz="-1.3334902286543242e-05" ixz="7.71539478534118e-06"/>
  </inertial>
  <visual>
    <origin xyz="-0.261365 0.138417 -0.0" rpy="0 0 0"/>
    <geometry>
      <mesh filename="meshes/finger_link321.stl" scale="0.001 0.001 0.001"/>
    </geometry>
    <material name="silver"/>
    <material/>
  </visual>
  <collision>
    <origin xyz="-0.261365 0.138417 -0.0" rpy="0 0 0"/>
    <geometry>
      <mesh filename="meshes/finger_link321.stl" scale="0.001 0.001 0.001"/>
    </geometry>
  </collision>
</link>

<link name="finger_link331">
  <inertial>
    <origin xyz="0.028913670476505338 -0.05000726394684843 0.0012630886709608779" rpy="0 0 0"/>
    <mass value="0.5898232192882596"/>
    <inertia ixx="0.0003501184522841441" iyy="0.00020815529240100772" izz="0.000489217164364994" ixy="0.0001343896412862866" iyz="-1.2008269609518587e-05" ixz="6.9506654285157894e-06"/>
  </inertial>
  <visual>
    <origin xyz="-0.302733 0.210068 -0.0" rpy="0 0 0"/>
    <geometry>
      <mesh filename="meshes/finger_link331.stl" scale="0.001 0.001 0.001"/>
    </geometry>
    <material name="silver"/>
    <material/>
  </visual>
  <collision>
    <origin xyz="-0.302733 0.210068 -0.0" rpy="0 0 0"/>
    <geometry>
      <mesh filename="meshes/finger_link331.stl" scale="0.001 0.001 0.001"/>
    </geometry>
  </collision>
</link>

<link name="finger_link111">
  <inertial>
    <origin xyz="-0.047410754994033424 -0.0002334006192142024 0.00923269398307338" rpy="0 0 0"/>
    <mass value="0.3396126943803763"/>
    <inertia ixx="6.969901470393685e-05" iyy="0.00021179457650051525" izz="0.0001914739675526406" ixy="-1.296353252055668e-06" iyz="4.2939463140188937e-07" ixz="3.084551770101015e-05"/>
  </inertial>
  <visual>
    <origin xyz="-0.167049 0.052925 0.01388" rpy="0 0 0"/>
    <geometry>
      <mesh filename="meshes/finger_link111.stl" scale="0.001 0.001 0.001"/>
    </geometry>
    <material name="silver"/>
    <material/>
  </visual>
  <collision>
    <origin xyz="-0.167049 0.052925 0.01388" rpy="0 0 0"/>
    <geometry>
      <mesh filename="meshes/finger_link111.stl" scale="0.001 0.001 0.001"/>
    </geometry>
  </collision>
</link>

<link name="finger2_ef1">
  <inertial>
    <origin xyz="0.017587144023619605 0.030064701054404258 -0.0006880018002984862" rpy="0 0 0"/>
    <mass value="0.23659461522625652"/>
    <inertia ixx="6.180398441654571e-05" iyy="5.480545881063337e-05" izz="0.0001017080441466367" ixy="-2.310281667011055e-06" iyz="1.178614534535199e-06" ixz="6.424809398637515e-07"/>
  </inertial>
  <visual>
    <origin xyz="-0.342368 -0.178868 -0.0" rpy="0 0 0"/>
    <geometry>
      <mesh filename="meshes/finger2_ef1.stl" scale="0.001 0.001 0.001"/>
    </geometry>
    <material name="silver"/>
    <material/>
  </visual>
  <collision>
    <origin xyz="-0.342368 -0.178868 -0.0" rpy="0 0 0"/>
    <geometry>
      <mesh filename="meshes/finger2_ef1.stl" scale="0.001 0.001 0.001"/>
    </geometry>
  </collision>
</link>

<link name="finger3_ef1">
  <inertial>
    <origin xyz="0.017243570863941238 -0.03026308681523182 -0.0006880018002984972" rpy="0 0 0"/>
    <mass value="0.23659461522625608"/>
    <inertia ixx="5.855585392226456e-05" iyy="5.805359078007999e-05" izz="0.00010170804562179697" ixy="4.185591959800922e-06" iyz="-1.1457120958078266e-06" ixz="6.994696658498597e-07"/>
  </inertial>
  <visual>
    <origin xyz="-0.3441 0.281718 -0.0" rpy="0 0 0"/>
    <geometry>
      <mesh filename="meshes/finger3_ef1.stl" scale="0.001 0.001 0.001"/>
    </geometry>
    <material name="silver"/>
    <material/>
  </visual>
  <collision>
    <origin xyz="-0.3441 0.281718 -0.0" rpy="0 0 0"/>
    <geometry>
      <mesh filename="meshes/finger3_ef1.stl" scale="0.001 0.001 0.001"/>
    </geometry>
  </collision>
</link>

<joint name="finger1_joint1" type="revolute">
  <origin xyz="-0.057224 0.0 0.01388" rpy="0 0 0"/>
  <parent link="finger_link111"/>
  <child link="finger_link121"/>
  <axis xyz="0.0 1.0 -0.0"/>
  <limit upper="1.570796" lower="0.0" effort="100" velocity="100"/>
</joint>
<transmission name="finger1_joint1_tran">
  <type>transmission_interface/SimpleTransmission</type>
  <joint name="finger1_joint1">
    <hardwareInterface>PositionJointInterface</hardwareInterface>
  </joint>
  <actuator name="finger1_joint1_actr">
    <hardwareInterface>PositionJointInterface</hardwareInterface>
    <mechanicalReduction>1</mechanicalReduction>
  </actuator>
</transmission>

<joint name="finger1_joint2" type="revolute">
  <origin xyz="-0.082735 0.0 0.0" rpy="0 0 0"/>
  <parent link="finger_link121"/>
  <child link="finger_link131"/>
  <axis xyz="0.0 1.0 -0.0"/>
  <limit upper="1.570796" lower="0.0" effort="100" velocity="100"/>
</joint>
<transmission name="finger1_joint2_tran">
  <type>transmission_interface/SimpleTransmission</type>
  <joint name="finger1_joint2">
    <hardwareInterface>PositionJointInterface</hardwareInterface>
  </joint>
  <actuator name="finger1_joint2_actr">
    <hardwareInterface>PositionJointInterface</hardwareInterface>
    <mechanicalReduction>1</mechanicalReduction>
  </actuator>
</transmission>

<joint name="finger1_joint3" type="revolute">
  <origin xyz="-0.082735 0.0 0.0" rpy="0 0 0"/>
  <parent link="finger_link131"/>
  <child link="finger1_ef1"/>
  <axis xyz="-0.0 1.0 -0.0"/>
  <limit upper="1.570796" lower="-1.570796" effort="100" velocity="100"/>
</joint>
<transmission name="finger1_joint3_tran">
  <type>transmission_interface/SimpleTransmission</type>
  <joint name="finger1_joint3">
    <hardwareInterface>PositionJointInterface</hardwareInterface>
  </joint>
  <actuator name="finger1_joint3_actr">
    <hardwareInterface>PositionJointInterface</hardwareInterface>
    <mechanicalReduction>1</mechanicalReduction>
  </actuator>
</transmission>

<joint name="finger2_palm" type="revolute">
  <origin xyz="0.231021 -0.013991 -0.01388" rpy="0 0 0"/>
  <parent link="base_link"/>
  <child link="finger_link211"/>
  <axis xyz="0.0 -0.0 1.0"/>
  <limit upper="1.047198" lower="-1.047198" effort="100" velocity="100"/>
</joint>
<transmission name="finger2_palm_tran">
  <type>transmission_interface/SimpleTransmission</type>
  <joint name="finger2_palm">
    <hardwareInterface>PositionJointInterface</hardwareInterface>
  </joint>
  <actuator name="finger2_palm_actr">
    <hardwareInterface>PositionJointInterface</hardwareInterface>
    <mechanicalReduction>1</mechanicalReduction>
  </actuator>
</transmission>

<joint name="finger2_joint1" type="revolute">
  <origin xyz="0.028612 0.049558 0.01388" rpy="0 0 0"/>
  <parent link="finger_link211"/>
  <child link="finger_link221"/>
  <axis xyz="0.866025 -0.5 -0.0"/>
  <limit upper="1.570796" lower="0.0" effort="100" velocity="100"/>
</joint>
<transmission name="finger2_joint1_tran">
  <type>transmission_interface/SimpleTransmission</type>
  <joint name="finger2_joint1">
    <hardwareInterface>PositionJointInterface</hardwareInterface>
  </joint>
  <actuator name="finger2_joint1_actr">
    <hardwareInterface>PositionJointInterface</hardwareInterface>
    <mechanicalReduction>1</mechanicalReduction>
  </actuator>
</transmission>

<joint name="finger2_joint2" type="revolute">
  <origin xyz="0.041368 0.071651 0.0" rpy="0 0 0"/>
  <parent link="finger_link221"/>
  <child link="finger_link231"/>
  <axis xyz="0.866025 -0.5 -0.0"/>
  <limit upper="1.570796" lower="0.0" effort="100" velocity="100"/>
</joint>
<transmission name="finger2_joint2_tran">
  <type>transmission_interface/SimpleTransmission</type>
  <joint name="finger2_joint2">
    <hardwareInterface>PositionJointInterface</hardwareInterface>
  </joint>
  <actuator name="finger2_joint2_actr">
    <hardwareInterface>PositionJointInterface</hardwareInterface>
    <mechanicalReduction>1</mechanicalReduction>
  </actuator>
</transmission>

<joint name="finger3_palm" type="revolute">
  <origin xyz="0.232753 -0.088859 -0.01388" rpy="0 0 0"/>
  <parent link="base_link"/>
  <child link="finger_link311"/>
  <axis xyz="-0.0 0.0 1.0"/>
  <limit upper="1.047198" lower="-1.047198" effort="100" velocity="100"/>
</joint>
<transmission name="finger3_palm_tran">
  <type>transmission_interface/SimpleTransmission</type>
  <joint name="finger3_palm">
    <hardwareInterface>PositionJointInterface</hardwareInterface>
  </joint>
  <actuator name="finger3_palm_actr">
    <hardwareInterface>PositionJointInterface</hardwareInterface>
    <mechanicalReduction>1</mechanicalReduction>
  </actuator>
</transmission>

<joint name="finger3_joint1" type="revolute">
  <origin xyz="0.028612 -0.049558 0.01388" rpy="0 0 0"/>
  <parent link="finger_link311"/>
  <child link="finger_link321"/>
  <axis xyz="-0.866025 -0.5 -0.0"/>
  <limit upper="1.570796" lower="0.0" effort="100" velocity="100"/>
</joint>
<transmission name="finger3_joint1_tran">
  <type>transmission_interface/SimpleTransmission</type>
  <joint name="finger3_joint1">
    <hardwareInterface>PositionJointInterface</hardwareInterface>
  </joint>
  <actuator name="finger3_joint1_actr">
    <hardwareInterface>PositionJointInterface</hardwareInterface>
    <mechanicalReduction>1</mechanicalReduction>
  </actuator>
</transmission>

<joint name="finger3_joint2" type="revolute">
  <origin xyz="0.041368 -0.071651 0.0" rpy="0 0 0"/>
  <parent link="finger_link321"/>
  <child link="finger_link331"/>
  <axis xyz="-0.866025 -0.5 0.0"/>
  <limit upper="1.570796" lower="0.0" effort="100" velocity="100"/>
</joint>
<transmission name="finger3_joint2_tran">
  <type>transmission_interface/SimpleTransmission</type>
  <joint name="finger3_joint2">
    <hardwareInterface>PositionJointInterface</hardwareInterface>
  </joint>
  <actuator name="finger3_joint2_actr">
    <hardwareInterface>PositionJointInterface</hardwareInterface>
    <mechanicalReduction>1</mechanicalReduction>
  </actuator>
</transmission>

<joint name="finger1_palm" type="revolute">
  <origin xyz="0.167049 -0.052925 -0.01388" rpy="0 0 0"/>
  <parent link="base_link"/>
  <child link="finger_link111"/>
  <axis xyz="0.0 0.0 1.0"/>
  <limit upper="1.047198" lower="-1.047198" effort="100" velocity="100"/>
</joint>
<transmission name="finger1_palm_tran">
  <type>transmission_interface/SimpleTransmission</type>
  <joint name="finger1_palm">
    <hardwareInterface>PositionJointInterface</hardwareInterface>
  </joint>
  <actuator name="finger1_palm_actr">
    <hardwareInterface>PositionJointInterface</hardwareInterface>
    <mechanicalReduction>1</mechanicalReduction>
  </actuator>
</transmission>

<joint name="finger2_joint3" type="revolute">
  <origin xyz="0.041367 0.07165 0.0" rpy="0 0 0"/>
  <parent link="finger_link231"/>
  <child link="finger2_ef1"/>
  <axis xyz="0.866025 -0.5 -0.0"/>
  <limit upper="1.570796" lower="-1.570796" effort="100" velocity="100"/>
</joint>
<transmission name="finger2_joint3_tran">
  <type>transmission_interface/SimpleTransmission</type>
  <joint name="finger2_joint3">
    <hardwareInterface>PositionJointInterface</hardwareInterface>
  </joint>
  <actuator name="finger2_joint3_actr">
    <hardwareInterface>PositionJointInterface</hardwareInterface>
    <mechanicalReduction>1</mechanicalReduction>
  </actuator>
</transmission>

<joint name="finger3_joint3" type="revolute">
  <origin xyz="0.041367 -0.07165 0.0" rpy="0 0 0"/>
  <parent link="finger_link331"/>
  <child link="finger3_ef1"/>
  <axis xyz="-0.866025 -0.5 0.0"/>
  <limit upper="1.570796" lower="-1.570796" effort="100" velocity="100"/>
</joint>
<transmission name="finger3_joint3_tran">
  <type>transmission_interface/SimpleTransmission</type>
  <joint name="finger3_joint3">
    <hardwareInterface>PositionJointInterface</hardwareInterface>
  </joint>
  <actuator name="finger3_joint3_actr">
    <hardwareInterface>PositionJointInterface</hardwareInterface>
    <mechanicalReduction>1</mechanicalReduction>
  </actuator>
</transmission>

</robot>
